Workbook

Sheet cg_loading
A1: Fill out the table below, use statistical data on the component weight fractions
C2: Unit | G2: Unit
A3: (x/c)OEW cg | B3: 0.15 | C3: fraction of MAC | E3: Fuselage length | F3: 36.466 | G3: m
B4: this one I didn't change from ADSEE, might not be ours | E4: Nacelle length | F4: ='Propultion System 2'!D27 -> 3.9 | G4: m
E5: MAC | F5: =Wing!B19 -> 3.4372349 | G5: m
E6: =IF(OR('Configuration Selection'!$B$13="Under wing",'Configuration Selection'!$B$13="Over wing",'Configuration Selection'!$B$13="Burried in the wing"),"x_hl","X_hl") -> X_hl | F6: =0.4*'Propultion System 2'!D27 -> 1.56 | G6: m
B8: fuselage group | E8: wing group
A9: item | B9: Mi | C9: Xi (m) | D9: MiXi (m) | E9: Mj | F9: xj (m) | G9: Mjxj (m)
A10: wing | E10: =B48 -> 0.197 | F10: 1.5 | G10: =E10*F10 -> 0.2955
A11: empennage | B11: =B49+B50 -> 0.043 | C11: 35.5 | D11: =B11*C11 -> 1.5265
A12: fuselage | B12: =B51 -> 0.35 | C12: 18.23 | D12: =B12*C12 -> 6.3805
A13: Main Landing gear | E13: =B52 -> 0.058 | F13: 1.7 | G13: =E13*F13 -> 0.0986
A14: propulsion | B14: =B54 -> 0.133 | C14: =28.6+F6 -> 30.16 | D14: =B14*C14 -> 4.01128
A15: Nose Landing gear | B15: 0.008 | C15: =21.63-18.8 -> 2.83 | D15: =B15*C15 -> 0.02264
A16: Cockpit Systems | B16: 0.023 | C16: 2.47 | D16: =B16*C16 -> 0.05681
A17: sum | B17: =SUM(B10:B16) -> 0.557 | C17: =SUM(D10:D16)/B17 -> 21.53991 | D17: =B17*C17 -> 11.99773 | E17: =SUM(E10:E16) -> 0.255 | F17: =SUM(G10:G16)/E17 -> 1.5454902 | G17: =E17*(F17+C20) -> 5.39465
D19: Unit
A20: Calculate the leading edge position of the MAC | B20: XLEMAC | C20: 19.61 | D20: m | G20: Last updated 30.03 | I20: =C20/'CRJ-1000 Loading Diagram'!C3 -> 0.53623188
B21: XTEMAC | C21: =C20+F5 -> 23.047235 | D21: m
A22: Next, calculate the CG travel during loading in the table below
A23: The loading diagram will be plotted automatically
A25: item | B25: Mi | C25: Xi (m) | D25: MiXi (m)
A26: OEW | B26: ='Mass Estimation'!B12 -> 0.5568684 | C26: 21.47 | D26: =B26*C26 -> 11.955964 | E26: =(D17+G17)/(B17+E17) -> 21.419187
A27: payload | B27: ='Mass Estimation'!B24 -> 0.2873439 | C27: 18.94 | D27: =B27*C27 -> 5.4422935 | E27: <--- calculation in payload stuff
A28: fuel | B28: ='Mass Estimation'!B5 -> 0.1557877 | C28: =C20+F5/4 -> 20.469309 | D28: =B28*C28 -> 3.1888666 | E28: <--- i'd say it's a reasonably reasonable assumption ( influences loading diagram a lot, so change to improve that)
A29: X_(WOE+WP) | B29: =B26+B27 -> 0.8442123 | C29: =((D26+D27)/(B29)) -> 20.608866
A30: X_(WOE+WP+WF) | B30: =B26+B27+B28 -> 1 | C30: =((D26+D27+D28)/(B30)) -> 20.587125
A31: X_(WOE+WF) | B31: =B26+B28 -> 0.7126561 | C31: =((D26+D28)/(B31)) -> 21.251247
G32: x
C33: Unit
A34: Most forward CG position | B34: =MIN(C29:C31) -> 20.587125 | C34: m
A35: Most aft CG position | B35: =MAX(C29:C31) -> 21.251247 | C35: m
A37: Copy the loading diagram that is generated from Excel to a program of your choice (paint, powerpoint, etc.). Save this as a separate image with the name <studentID>_loadingDiagram.jpg
A39: Complete aircraft 3 view drawings
A40: Now that you know the position of the wing from the leading edge MAC position, you can make a 3 view drawing of your aircraft.
A41: Complete the 3 view drawings of your aircraft. Combine wing, fuselage and propulsion systems in the different views. Indicate the CG positions (OEW, forward, aft) in the side view.
A43: Make a picture of your drawing, this may come in handy later!
B47: frac | C47: mass
A48: Wing | B48: 0.197 | C48: =B48*'Mass Estimation'!$B$16 -> 4568.036
A49: Horizontal Tail | B49: 0.025 | C49: =B49*'Mass Estimation'!$B$16 -> 579.7
...

Sheet cg_loading_exx
A1: Fill out the table below, use statistical data on the component weight fractions
C2: Unit | G2: Unit
E3: Fuselage length | F3: 36.466 | G3: m
E4: Nacelle length | F4: ='Propultion System 2'!D27 -> 3.9 | G4: m
E5: MAC | F5: =Wing!B19 -> 3.4372349 | G5: m
E6: =IF(OR('Configuration Selection'!$B$13="Under wing",'Configuration Selection'!$B$13="Over wing",'Configuration Selection'!$B$13="Burried in the wing"),"x_hl","X_hl") -> X_hl | F6: =0.4*'Propultion System 2'!D27 -> 1.56 | G6: m
B8: fuselage group | E8: wing group
A9: item | B9: Mi | C9: Xi (m) | D9: MiXi (m) | E9: Mj | F9: xj (m) | G9: Mjxj (m)
A10: wing | E10: =C58 -> 0.18483002 | F10: =cg_loading!F10 -> 1.5 | G10: =E10*F10 -> 0.27724503
A11: empennage | B11: =C59+C60 -> 0.044333636 | C11: =cg_loading!C11 -> 35.5 | D11: =B11*C11 -> 1.5738441
A12: fuselage | B12: =C61 -> 0.33559532 | C12: =cg_loading!C12 -> 18.23 | D12: =B12*C12 -> 6.1179026
A13: Main Landing gear | E13: =C62 -> 0.070477226 | F13: =cg_loading!F13 -> 1.7 | G13: =E13*F13 -> 0.11981128
A14: propulsion | B14: =C64 -> 0.13712497 | C14: =cg_loading!C14 -> 30.16 | D14: =B14*C14 -> 4.135689
A15: Nose Landing gear | B15: =C63 -> 0.010094712 | C15: =cg_loading!C15 -> 2.83 | D15: =B15*C15 -> 0.028568035
A16: Cockpit Systems | B16: 0.023 | C16: =cg_loading!C16 -> 2.47 | D16: =B16*C16 -> 0.05681
A17: sum | B17: =SUM(B10:B16) -> 0.55014863 | C17: =SUM(D10:D16)/B17 -> 21.65381 | E17: =SUM(E10:E16) -> 0.25530725 | F17: =SUM(G10:G16)/E17 -> 1.5552097
D19: Unit
A20: Calculate the leading edge position of the MAC | B20: XLEMAC | C20: 19.61 | D20: m | G20: Last updated 1.04
B21: XTEMAC | C21: =C20+F5 -> 23.047235 | D21: m
A22: Next, calculate the CG travel during loading in the table below
A23: The loading diagram will be plotted automatically
A25: item | B25: Mi | C25: Xi (m) | D25: MiXi (m)
A26: OEW | B26: =B68/'Weight Pie Charts'!D36 -> 0.54011679 | C26: =(B17*C17+E17*(F17+C20))/(B17+E17) -> 21.498937 | D26: =B26*C26 -> 11.611937
A27: Batteries | B27: =H65/'Weight Pie Charts'!D36 -> 0.10806916 | C27: =G65 -> 21.304863 | D27: =B27*C27 -> 2.3023987
A28: payload | B28: =H66/'Weight Pie Charts'!D36 -> 0.2622488 | C28: =G66 -> 18.368629 | D28: =B28*C28 -> 4.817151
A29: payload w/ batteries | B29: =SUM(B27:B28) -> 0.37031796 | C29: 18.94 | D29: =B29*C29 -> 7.0138222 | E29: <--- calculation in bottom right
A30: fuel | B30: =1-B29-B26 -> 0.089565251 | C30: =cg_loading!C28 -> 20.469309 | D30: =B30*C30 -> 1.8333388 | E30: <--- i'd say it's a reasonably reasonable assumption ( influences loading diagram a lot, so change to improve that)
A31: X_(WOE+WP) | B31: =B26+B28 -> 0.80236558 | C31: =((D26+D29)/(B31)) -> 23.213557
A32: X_(WOE+WP+WF) | B32: =B26+B28+B30 -> 0.89193084 | C32: =((D26+D29+D30)/(B32)) -> 22.937987
A33: X_(WOE+WF) | B33: =B26+B30 -> 0.62968204 | C33: =((D26+D30)/(B33)) -> 21.352484
A34: X_(WOE+B) | B34: =B26+B27 -> 0.64818595 | C34: =(D26+D27)/(B34) -> 21.46658 | G34: x
A35: X_(WOE+WP+B) | B35: =B26+B28+B27 -> 0.91043475 | C35: =(D26+D28+D27)/(B35) -> 20.574222
A36: X_(WOE+WF+B) | B36: =B26+B30+B27 -> 0.7377512 | C36: =(D26+D30+D27)/(B36) -> 21.345508
A37: X_(WOE+WF+WP+B) | B37: =B26+B30+B28+B27 -> 1 | C37: =(D26+D30+D28+D27)/(B37) -> 20.564825
A38: Red not used in loading diagram
B39: =B30*'Weight Pie Charts'!D7 -> 3729.4971
C43: Unit | O43: OEW | P43: =B26 -> 0.54011679
A44: Most forward CG position | B44: =MIN(C31:C33) -> 21.352484 | C44: m | O44: Wp(cabin) | P44: =H64/'Weight Pie Charts'!D36 -> 0.18403074
A45: Most aft CG position | B45: =MAX(C31:C33) -> 23.213557 | C45: m | O45: WF | P45: =B30 -> 0.089565251
O46: Wbat(aft) | P46: =H63/'Weight Pie Charts'!D36 -> 0.05943804
...

Sheet CRJ-1000 Loading Diagram
B2: MAC | C2: =cg_loading!F5 -> 3.4372349
B3: lf | C3: =36.57 -> 36.57 | G3: mass [kg] | H3: x_front [m] | I3: moment [kg*m] | J3: mass total [kg] | K3: moment total [kg*m] | L3: xcg_nose [m] | M3: xcg_lemac [m] | N3: xcg_lemac_mac [-] | R3: mass [kg] | S3: x_front [m] | T3: moment [kg*m] | U3: mass total [kg] | V3: moment total [kg*m] | W3: xcg_nose [m] | X3: xcg_lemac [m] | Y3: xcg_lemac_mac [-]
B4: x_LEMAC/lf | C4: =cg_loading!I20 -> 0.53623188 | F4: OEW | G4: ='Weight Pie Charts'!D9 -> 23188 | H4: =cg_loading!C26 -> 21.47 | I4: =G4*H4 -> 497846.36 | J4: =G4 -> 23188 | K4: =I4 -> 497846.36 | L4: =K4/J4 -> 21.47 | M4: =L4-C$5 -> 1.86 | N4: =M4/C$2 -> 0.54113264 | Q4: OEW | R4: =G4 -> 23188 | S4: =H4 -> 21.47 | T4: =R4*S4 -> 497846.36 | U4: =R4 -> 23188 | V4: =T4 -> 497846.36 | W4: =V4/U4 -> 21.47 | X4: =W4-C$5 -> 1.86 | Y4: =X4/C$2 -> 0.54113264
B5: x_LEMAC | C5: =C3*C4 -> 19.61 | E5: cargo | F5: cargo aft | G5: ='Weight Pie Charts'!D27 -> 2386.0381 | H5: ='pay, load, stuff'!E4 -> 29.15 | I5: =G5*H5 -> 69553.011 | J5: =J4+G5 -> 25574.038 | K5: =K4+I5 -> 567399.37 | L5: =K5/J5 -> 22.186538 | M5: =L5-C$5 -> 2.5765381 | N5: =M5/C$2 -> 0.74959617 | Q5: cargo front | R5: =G6 -> 870.96187 | S5: =H6 -> 10.94 | T5: =R5*S5 -> 9528.3229 | U5: =U4+R5 -> 24058.962 | V5: =V4+T5 -> 507374.68 | W5: =V5/U5 -> 21.088802 | X5: =W5-C$5 -> 1.478802 | Y5: =X5/C$2 -> 0.43023012
F6: cargo front | G6: ='Weight Pie Charts'!D26 -> 870.96187 | H6: ='pay, load, stuff'!D4 -> 10.94 | I6: =G6*H6 -> 9528.3229 | J6: =J5+G6 -> 26445 | K6: =K5+I6 -> 576927.69 | L6: =K6/J6 -> 21.816135 | M6: =L6-C$5 -> 2.2061352 | N6: =M6/C$2 -> 0.64183427 | Q6: cargo aft | R6: =G5 -> 2386.0381 | S6: =H5 -> 29.15 | T6: =R6*S6 -> 69553.011 | U6: =U5+R6 -> 26445 | V6: =V5+T6 -> 576927.69 | W6: =V6/U6 -> 21.816135 | X6: =W6-C$5 -> 2.2061352 | Y6: =X6/C$2 -> 0.64183427
B7: Standard person mass | C7: ='Weight Pie Charts'!D10/100 -> 87.08 | E7: back to front | F7: w row 25 | G7: =C$8/2*C$7 -> 174.16 | H7: =C42+24*C9+C9/2 -> 24.9413 | I7: =G7*H7 -> 4343.7768 | J7: =J6+G7 -> 26619.16 | K7: =K6+I7 -> 581271.47 | L7: =K7/J7 -> 21.836582 | M7: =L7-C$5 -> 2.226582 | N7: =M7/C$2 -> 0.64778291 | P7: front to back | Q7: w row 1 | R7: =C$8*C$7/2 -> 174.16 | S7: =C42+C9/2 -> 6.0437 | T7: =R7*S7 -> 1052.5708 | U7: =U6+R7 -> 26619.16 | V7: =V6+T7 -> 577980.27 | W7: =V7/U7 -> 21.712942 | X7: =W7-C$5 -> 2.1029415 | Y7: =X7/C$2 -> 0.611812
B8: pax per row | C8: 4 | F8: w row 24 | G8: =C$8/2*C$7 -> 174.16 | H8: =H7-C$9 -> 24.1539 | I8: =G8*H8 -> 4206.6432 | J8: =J7+G8 -> 26793.32 | K8: =K7+I8 -> 585478.11 | L8: =K8/J8 -> 21.851645 | M8: =L8-C$5 -> 2.2416449 | N8: =M8/C$2 -> 0.65216518 | Q8: w row 2 | R8: =C$8*C$7/2 -> 174.16 | S8: =S7+C$9 -> 6.8311 | T8: =R8*S8 -> 1189.7044 | U8: =U7+R8 -> 26793.32 | V8: =V7+T8 -> 579169.97 | W8: =V8/U8 -> 21.616208 | X8: =W8-C$5 -> 2.0062077 | Y8: =X8/C$2 -> 0.58366906
B9: seat pitch [m] | C9: =31*0.0254 -> 0.7874 | F9: w row 23 | G9: =C$8/2*C$7 -> 174.16 | H9: =H8-C$9 -> 23.3665 | I9: =G9*H9 -> 4069.5096 | J9: =J8+G9 -> 26967.48 | K9: =K8+I9 -> 589547.62 | L9: =K9/J9 -> 21.861428 | M9: =L9-C$5 -> 2.2514281 | N9: =M9/C$2 -> 0.65501141 | Q9: w row 3 | R9: =C$8*C$7/2 -> 174.16 | S9: =S8+C$9 -> 7.6185 | T9: =R9*S9 -> 1326.838 | U9: =U8+R9 -> 26967.48 | V9: =V8+T9 -> 580496.81 | W9: =V9/U9 -> 21.525808 | X9: =W9-C$5 -> 1.9158084 | Y9: =X9/C$2 -> 0.55736906
F10: w row 22 | G10: =C$8/2*C$7 -> 174.16 | H10: =H9-C$9 -> 22.5791 | I10: =G10*H10 -> 3932.3761 | J10: =J9+G10 -> 27141.64 | K10: =K9+I10 -> 593480 | L10: =K10/J10 -> 21.866033 | M10: =L10-C$5 -> 2.2560332 | N10: =M10/C$2 -> 0.65635117 | Q10: w row 4 | R10: =C$8*C$7/2 -> 174.16 | S10: =S9+C$9 -> 8.4059 | T10: =R10*S10 -> 1463.9715 | U10: =U9+R10 -> 27141.64 | V10: =V9+T10 -> 581960.78 | W10: =V10/U10 -> 21.441622 | X10: =W10-C$5 -> 1.8316218 | Y10: =X10/C$2 -> 0.53287652
B11: I made this sheet to set up an Excel for the loading diagram described in "Generation of Loading Diagram and determination of optimum tail surface" (Additional Material in Brightspace). | F11: w row 21 | G11: =C$8/2*C$7 -> 174.16 | H11: =H10-C$9 -> 21.7917 | I11: =G11*H11 -> 3795.2425 | J11: =J10+G11 -> 27315.8 | K11: =K10+I11 -> 597275.24 | L11: =K11/J11 -> 21.865559 | M11: =L11-C$5 -> 2.2555592 | N11: =M11/C$2 -> 0.65621329 | Q11: w row 5 | R11: =C$8*C$7/2 -> 174.16 | S11: =S10+C$9 -> 9.1933 | T11: =R11*S11 -> 1601.1051 | U11: =U10+R11 -> 27315.8 | V11: =V10+T11 -> 583561.88 | W11: =V11/U11 -> 21.363529 | X11: =W11-C$5 -> 1.753529 | Y11: =X11/C$2 -> 0.51015686
F12: w row 20 | G12: =C$8/2*C$7 -> 174.16 | H12: =H11-C$9 -> 21.0043 | I12: =G12*H12 -> 3658.1089 | J12: =J11+G12 -> 27489.96 | K12: =K11+I12 -> 600933.35 | L12: =K12/J12 -> 21.860103 | M12: =L12-C$5 -> 2.2501028 | N12: =M12/C$2 -> 0.65462584 | Q12: w row 6 | R12: =C$8*C$7/2 -> 174.16 | S12: =S11+C$9 -> 9.9807 | T12: =R12*S12 -> 1738.2387 | U12: =U11+R12 -> 27489.96 | V12: =V11+T12 -> 585300.12 | W12: =V12/U12 -> 21.291414 | X12: =W12-C$5 -> 1.6814141 | Y12: =X12/C$2 -> 0.48917638
F13: w row 19 | G13: =C$8/2*C$7 -> 174.16 | H13: =H12-C$9 -> 20.2169 | I13: =G13*H13 -> 3520.9753 | J13: =J12+G13 -> 27664.12 | K13: =K12+I13 -> 604454.33 | L13: =K13/J13 -> 21.849758 | M13: =L13-C$5 -> 2.239758 | N13: =M13/C$2 -> 0.65161621 | Q13: w row 7 | R13: =C$8*C$7/2 -> 174.16 | S13: =S12+C$9 -> 10.7681 | T13: =R13*S13 -> 1875.3723 | U13: =U12+R13 -> 27664.12 | V13: =V12+T13 -> 587175.5 | W13: =V13/U13 -> 21.225164 | X13: =W13-C$5 -> 1.6151644 | Y13: =X13/C$2 -> 0.46990225
F14: w row 18 | G14: =C$8/2*C$7 -> 174.16 | H14: =H13-C$9 -> 19.4295 | I14: =G14*H14 -> 3383.8417 | J14: =J13+G14 -> 27838.28 | K14: =K13+I14 -> 607838.17 | L14: =K14/J14 -> 21.834617 | M14: =L14-C$5 -> 2.2246165 | N14: =M14/C$2 -> 0.64721108 | Q14: w row 8 | R14: =C$8*C$7/2 -> 174.16 | S14: =S13+C$9 -> 11.5555 | T14: =R14*S14 -> 2012.5059 | U14: =U13+R14 -> 27838.28 | V14: =V13+T14 -> 589188 | W14: =V14/U14 -> 21.16467 | X14: =W14-C$5 -> 1.5546697 | Y14: =X14/C$2 -> 0.45230243
F15: w row 17 | G15: =C$8/2*C$7 -> 174.16 | H15: =H14-C$9 -> 18.6421 | I15: =G15*H15 -> 3246.7081 | J15: =J14+G15 -> 28012.44 | K15: =K14+I15 -> 611084.88 | L15: =K15/J15 -> 21.814768 | M15: =L15-C$5 -> 2.2047679 | N15: =M15/C$2 -> 0.64143649 | Q15: w row 9 | R15: =C$8*C$7/2 -> 174.16 | S15: =S14+C$9 -> 12.3429 | T15: =R15*S15 -> 2149.6395 | U15: =U14+R15 -> 28012.44 | V15: =V14+T15 -> 591337.64 | W15: =V15/U15 -> 21.109823 | X15: =W15-C$5 -> 1.4998227 | Y15: =X15/C$2 -> 0.4363457
F16: w row 16 | G16: =C$8/2*C$7 -> 174.16 | H16: =H15-C$9 -> 17.8547 | I16: =G16*H16 -> 3109.5746 | J16: =J15+G16 -> 28186.6 | K16: =K15+I16 -> 614194.45 | L16: =K16/J16 -> 21.790299 | M16: =L16-C$5 -> 2.1802993 | N16: =M16/C$2 -> 0.63431782 | Q16: w row 10 | R16: =C$8*C$7/2 -> 174.16 | S16: =S15+C$9 -> 13.1303 | T16: =R16*S16 -> 2286.773 | U16: =U15+R16 -> 28186.6 | V16: =V15+T16 -> 593624.41 | W16: =V16/U16 -> 21.060519 | X16: =W16-C$5 -> 1.4505186 | Y16: =X16/C$2 -> 0.42200159
F17: w row 15 | G17: =C$8/2*C$7 -> 174.16 | H17: =H16-C$9 -> 17.0673 | I17: =G17*H17 -> 2972.441 | J17: =J16+G17 -> 28360.76 | K17: =K16+I17 -> 617166.89 | L17: =K17/J17 -> 21.761296 | M17: =L17-C$5 -> 2.151296 | N17: =M17/C$2 -> 0.62587982 | Q17: w row 11 | R17: =C$8*C$7/2 -> 174.16 | S17: =S16+C$9 -> 13.9177 | T17: =R17*S17 -> 2423.9066 | U17: =U16+R17 -> 28360.76 | V17: =V16+T17 -> 596048.32 | W17: =V17/U17 -> 21.016655 | X17: =W17-C$5 -> 1.4066554 | Y17: =X17/C$2 -> 0.40924041
F18: w row 14 | G18: =C$8/2*C$7 -> 174.16 | H18: =H17-C$9 -> 16.2799 | I18: =G18*H18 -> 2835.3074 | J18: =J17+G18 -> 28534.92 | K18: =K17+I18 -> 620002.2 | L18: =K18/J18 -> 21.727841 | M18: =L18-C$5 -> 2.1178408 | N18: =M18/C$2 -> 0.61614666 | Q18: w row 12 | R18: =C$8*C$7/2 -> 174.16 | S18: =S17+C$9 -> 14.7051 | T18: =R18*S18 -> 2561.0402 | U18: =U17+R18 -> 28534.92 | V18: =V17+T18 -> 598609.36 | W18: =V18/U18 -> 20.978133 | X18: =W18-C$5 -> 1.3681335 | Y18: =X18/C$2 -> 0.39803316
F19: w row 13 | G19: =C$8/2*C$7 -> 174.16 | H19: =H18-C$9 -> 15.4925 | I19: =G19*H19 -> 2698.1738 | J19: =J18+G19 -> 28709.08 | K19: =K18+I19 -> 622700.37 | L19: =K19/J19 -> 21.690015 | M19: =L19-C$5 -> 2.0800149 | N19: =M19/C$2 -> 0.60514192 | Q19: w row 13 | R19: =C$8*C$7/2 -> 174.16 | S19: =S18+C$9 -> 15.4925 | T19: =R19*S19 -> 2698.1738 | U19: =U18+R19 -> 28709.08 | V19: =V18+T19 -> 601307.53 | W19: =V19/U19 -> 20.944856 | X19: =W19-C$5 -> 1.3348556 | Y19: =X19/C$2 -> 0.38835157
B20: 28.03.2026 Update: I set up the masses for OEW, cargo, passengers and fuel, but I am lacking some geometric parameters, so the sheet is not working as it should (yet). Ideally, it should compute the parameters for boarding back to front and front to back. | F20: w row 12 | G20: =C$8/2*C$7 -> 174.16 | H20: =H19-C$9 -> 14.7051 | I20: =G20*H20 -> 2561.0402 | J20: =J19+G20 -> 28883.24 | K20: =K19+I20 -> 625261.41 | L20: =K20/J20 -> 21.647897 | M20: =L20-C$5 -> 2.0378973 | N20: =M20/C$2 -> 0.59288858 | Q20: w row 14 | R20: =C$8*C$7/2 -> 174.16 | S20: =S19+C$9 -> 16.2799 | T20: =R20*S20 -> 2835.3074 | U20: =U19+R20 -> 28883.24 | V20: =V19+T20 -> 604142.84 | W20: =V20/U20 -> 20.916727 | X20: =W20-C$5 -> 1.3067268 | Y20: =X20/C$2 -> 0.38016804
F21: w row 11 | G21: =C$8/2*C$7 -> 174.16 | H21: =H20-C$9 -> 13.9177 | I21: =G21*H21 -> 2423.9066 | J21: =J20+G21 -> 29057.4 | K21: =K20+I21 -> 627685.32 | L21: =K21/J21 -> 21.601565 | M21: =L21-C$5 -> 1.9915652 | N21: =M21/C$2 -> 0.5794091 | Q21: w row 15 | R21: =C$8*C$7/2 -> 174.16 | S21: =S20+C$9 -> 17.0673 | T21: =R21*S21 -> 2972.441 | U21: =U20+R21 -> 29057.4 | V21: =V20+T21 -> 607115.28 | W21: =V21/U21 -> 20.893655 | X21: =W21-C$5 -> 1.2836547 | Y21: =X21/C$2 -> 0.37345563
F22: w row 10 | G22: =C$8/2*C$7 -> 174.16 | H22: =H21-C$9 -> 13.1303 | I22: =G22*H22 -> 2286.773 | J22: =J21+G22 -> 29231.56 | K22: =K21+I22 -> 629972.09 | L22: =K22/J22 -> 21.551094 | M22: =L22-C$5 -> 1.9410939 | N22: =M22/C$2 -> 0.5647254 | Q22: w row 16 | R22: =C$8*C$7/2 -> 174.16 | S22: =S21+C$9 -> 17.8547 | T22: =R22*S22 -> 3109.5746 | U22: =U21+R22 -> 29231.56 | V22: =V21+T22 -> 610224.86 | W22: =V22/U22 -> 20.875549 | X22: =W22-C$5 -> 1.2655488 | Y22: =X22/C$2 -> 0.36818804
F23: w row 9 | G23: =C$8/2*C$7 -> 174.16 | H23: =H22-C$9 -> 12.3429 | I23: =G23*H23 -> 2149.6395 | J23: =J22+G23 -> 29405.72 | K23: =K22+I23 -> 632121.73 | L23: =K23/J23 -> 21.496557 | M23: =L23-C$5 -> 1.8865569 | N23: =M23/C$2 -> 0.54885888 | Q23: w row 17 | R23: =C$8*C$7/2 -> 174.16 | S23: =S22+C$9 -> 18.6421 | T23: =R23*S23 -> 3246.7081 | U23: =U22+R23 -> 29405.72 | V23: =V22+T23 -> 613471.57 | W23: =V23/U23 -> 20.862321 | X23: =W23-C$5 -> 1.2523208 | Y23: =X23/C$2 -> 0.36433962
F24: w row 8 | G24: =C$8/2*C$7 -> 174.16 | H24: =H23-C$9 -> 11.5555 | I24: =G24*H24 -> 2012.5059 | J24: =J23+G24 -> 29579.88 | K24: =K23+I24 -> 634134.24 | L24: =K24/J24 -> 21.438026 | M24: =L24-C$5 -> 1.8280261 | N24: =M24/C$2 -> 0.53183042 | Q24: w row 18 | R24: =C$8*C$7/2 -> 174.16 | S24: =S23+C$9 -> 19.4295 | T24: =R24*S24 -> 3383.8417 | U24: =U23+R24 -> 29579.88 | V24: =V23+T24 -> 616855.41 | W24: =V24/U24 -> 20.853885 | X24: =W24-C$5 -> 1.2438847 | Y24: =X24/C$2 -> 0.36188528
F25: w row 7 | G25: =C$8/2*C$7 -> 174.16 | H25: =H24-C$9 -> 10.7681 | I25: =G25*H25 -> 1875.3723 | J25: =J24+G25 -> 29754.04 | K25: =K24+I25 -> 636009.61 | L25: =K25/J25 -> 21.375572 | M25: =L25-C$5 -> 1.7655715 | N25: =M25/C$2 -> 0.51366043 | Q25: w row 19 | R25: =C$8*C$7/2 -> 174.16 | S25: =S24+C$9 -> 20.2169 | T25: =R25*S25 -> 3520.9753 | U25: =U24+R25 -> 29754.04 | V25: =V24+T25 -> 620376.38 | W25: =V25/U25 -> 20.850156 | X25: =W25-C$5 -> 1.2401562 | Y25: =X25/C$2 -> 0.36080054
F26: w row 6 | G26: =C$8/2*C$7 -> 174.16 | H26: =H25-C$9 -> 9.9807 | I26: =G26*H26 -> 1738.2387 | J26: =J25+G26 -> 29928.2 | K26: =K25+I26 -> 637747.85 | L26: =K26/J26 -> 21.309262 | M26: =L26-C$5 -> 1.6992618 | N26: =M26/C$2 -> 0.49436884 | Q26: w row 20 | R26: =C$8*C$7/2 -> 174.16 | S26: =S25+C$9 -> 21.0043 | T26: =R26*S26 -> 3658.1089 | U26: =U25+R26 -> 29928.2 | V26: =V25+T26 -> 624034.49 | W26: =V26/U26 -> 20.851053 | X26: =W26-C$5 -> 1.2410532 | Y26: =X26/C$2 -> 0.36106151
F27: w row 5 | G27: =C$8/2*C$7 -> 174.16 | H27: =H26-C$9 -> 9.1933 | I27: =G27*H27 -> 1601.1051 | J27: =J26+G27 -> 30102.36 | K27: =K26+I27 -> 639348.95 | L27: =K27/J27 -> 21.239164 | M27: =L27-C$5 -> 1.6291638 | N27: =M27/C$2 -> 0.47397511 | Q27: w row 21 | R27: =C$8*C$7/2 -> 174.16 | S27: =S26+C$9 -> 21.7917 | T27: =R27*S27 -> 3795.2425 | U27: =U26+R27 -> 30102.36 | V27: =V26+T27 -> 627829.73 | W27: =V27/U27 -> 20.856495 | X27: =W27-C$5 -> 1.2464954 | Y27: =X27/C$2 -> 0.36264482
B28: All cells in yellow have values that need to be calculated manually, the ones you see for now were (poorly) eyeballed! | F28: w row 4 | G28: =C$8/2*C$7 -> 174.16 | H28: =H27-C$9 -> 8.4059 | I28: =G28*H28 -> 1463.9715 | J28: =J27+G28 -> 30276.52 | K28: =K27+I28 -> 640812.93 | L28: =K28/J28 -> 21.165343 | M28: =L28-C$5 -> 1.5553429 | N28: =M28/C$2 -> 0.45249827 | Q28: w row 22 | R28: =C$8*C$7/2 -> 174.16 | S28: =S27+C$9 -> 22.5791 | T28: =R28*S28 -> 3932.3761 | U28: =U27+R28 -> 30276.52 | V28: =V27+T28 -> 631762.11 | W28: =V28/U28 -> 20.866404 | X28: =W28-C$5 -> 1.2564044 | Y28: =X28/C$2 -> 0.36552765
F29: w row 3 | G29: =C$8/2*C$7 -> 174.16 | H29: =H28-C$9 -> 7.6185 | I29: =G29*H29 -> 1326.838 | J29: =J28+G29 -> 30450.68 | K29: =K28+I29 -> 642139.76 | L29: =K29/J29 -> 21.087863 | M29: =L29-C$5 -> 1.4778629 | N29: =M29/C$2 -> 0.4299569 | Q29: w row 23 | R29: =C$8*C$7/2 -> 174.16 | S29: =S28+C$9 -> 23.3665 | T29: =R29*S29 -> 4069.5096 | U29: =U28+R29 -> 30450.68 | V29: =V28+T29 -> 635831.62 | W29: =V29/U29 -> 20.880703 | X29: =W29-C$5 -> 1.2707035 | Y29: =X29/C$2 -> 0.3696877
F30: w row 2 | G30: =C$8/2*C$7 -> 174.16 | H30: =H29-C$9 -> 6.8311 | I30: =G30*H30 -> 1189.7044 | J30: =J29+G30 -> 30624.84 | K30: =K29+I30 -> 643329.47 | L30: =K30/J30 -> 21.006786 | M30: =L30-C$5 -> 1.3967863 | N30: =M30/C$2 -> 0.40636916 | Q30: w row 24 | R30: =C$8*C$7/2 -> 174.16 | S30: =S29+C$9 -> 24.1539 | T30: =R30*S30 -> 4206.6432 | U30: =U29+R30 -> 30624.84 | V30: =V29+T30 -> 640038.26 | W30: =V30/U30 -> 20.899318 | X30: =W30-C$5 -> 1.2893178 | Y30: =X30/C$2 -> 0.37510319
B31: The values have now been somewhat improved | F31: w row 1 | G31: =C$8/2*C$7 -> 174.16 | H31: =H30-C$9 -> 6.0437 | I31: =G31*H31 -> 1052.5708 | J31: =J30+G31 -> 30799 | K31: =K30+I31 -> 644382.04 | L31: =K31/J31 -> 20.922174 | M31: =L31-C$5 -> 1.3121741 | N31: =M31/C$2 -> 0.38175281 | Q31: w row 25 | R31: =C$8*C$7/2 -> 174.16 | S31: =S30+C$9 -> 24.9413 | T31: =R31*S31 -> 4343.7768 | U31: =U30+R31 -> 30799 | V31: =V30+T31 -> 644382.04 | W31: =V31/U31 -> 20.922174 | X31: =W31-C$5 -> 1.3121741 | Y31: =X31/C$2 -> 0.38175281
B32: All cells in pink take their values from cg_loading! | F32: a row 25 | G32: =C$8/2*C$7 -> 174.16 | H32: =H7 -> 24.9413 | I32: =G32*H32 -> 4343.7768 | J32: =J31+G32 -> 30973.16 | K32: =K31+I32 -> 648725.82 | L32: =K32/J32 -> 20.944773 | M32: =L32-C$5 -> 1.3347734 | N32: =M32/C$2 -> 0.38832765 | Q32: a row 1 | R32: =C$8*C$7/2 -> 174.16 | S32: =S7 -> 6.0437 | T32: =R32*S32 -> 1052.5708 | U32: =U31+R32 -> 30973.16 | V32: =V31+T32 -> 645434.61 | W32: =V32/U32 -> 20.838513 | X32: =W32-C$5 -> 1.2285134 | Y32: =X32/C$2 -> 0.35741328
F33: a row 24 | G33: =C$8/2*C$7 -> 174.16 | H33: =H8 -> 24.1539 | I33: =G33*H33 -> 4206.6432 | J33: =J32+G33 -> 31147.32 | K33: =K32+I33 -> 652932.46 | L33: =K33/J33 -> 20.962717 | M33: =L33-C$5 -> 1.3527172 | N33: =M33/C$2 -> 0.39354807 | Q33: a row 2 | R33: =C$8*C$7/2 -> 174.16 | S33: =S32+C$9 -> 6.8311 | T33: =R33*S33 -> 1189.7044 | U33: =U32+R33 -> 31147.32 | V33: =V32+T33 -> 646624.31 | W33: =V33/U33 -> 20.760191 | X33: =W33-C$5 -> 1.1501911 | Y33: =X33/C$2 -> 0.33462684
B34: pink??? | F34: a row 23 | G34: =C$8/2*C$7 -> 174.16 | H34: =H9 -> 23.3665 | I34: =G34*H34 -> 4069.5096 | J34: =J33+G34 -> 31321.48 | K34: =K33+I34 -> 657001.97 | L34: =K34/J34 -> 20.976083 | M34: =L34-C$5 -> 1.3660832 | N34: =M34/C$2 -> 0.39743666 | Q34: a row 3 | R34: =C$8*C$7/2 -> 174.16 | S34: =S33+C$9 -> 7.6185 | T34: =R34*S34 -> 1326.838 | U34: =U33+R34 -> 31321.48 | V34: =V33+T34 -> 647951.15 | W34: =V34/U34 -> 20.687118 | X34: =W34-C$5 -> 1.077118 | Y34: =X34/C$2 -> 0.31336758
B35: All cells in blue take their values from Weight Pie Chart! | F35: a row 22 | G35: =C$8/2*C$7 -> 174.16 | H35: =H10 -> 22.5791 | I35: =G35*H35 -> 3932.3761 | J35: =J34+G35 -> 31495.64 | K35: =K34+I35 -> 660934.35 | L35: =K35/J35 -> 20.984947 | M35: =L35-C$5 -> 1.3749473 | N35: =M35/C$2 -> 0.40001551 | Q35: a row 4 | R35: =C$8*C$7/2 -> 174.16 | S35: =S34+C$9 -> 8.4059 | T35: =R35*S35 -> 1463.9715 | U35: =U34+R35 -> 31495.64 | V35: =V34+T35 -> 649415.12 | W35: =V35/U35 -> 20.619207 | X35: =W35-C$5 -> 1.0092071 | Y35: =X35/C$2 -> 0.29361016
F36: a row 21 | G36: =C$8/2*C$7 -> 174.16 | H36: =H11 -> 21.7917 | I36: =G36*H36 -> 3795.2425 | J36: =J35+G36 -> 31669.8 | K36: =K35+I36 -> 664729.59 | L36: =K36/J36 -> 20.989384 | M36: =L36-C$5 -> 1.3793838 | N36: =M36/C$2 -> 0.40130624 | Q36: a row 5 | R36: =C$8*C$7/2 -> 174.16 | S36: =S35+C$9 -> 9.1933 | T36: =R36*S36 -> 1601.1051 | U36: =U35+R36 -> 31669.8 | V36: =V35+T36 -> 651016.23 | W36: =V36/U36 -> 20.556373 | X36: =W36-C$5 -> 0.94637324 | Y36: =X36/C$2 -> 0.27532981
F37: a row 20 | G37: =C$8/2*C$7 -> 174.16 | H37: =H12 -> 21.0043 | I37: =G37*H37 -> 3658.1089 | J37: =J36+G37 -> 31843.96 | K37: =K36+I37 -> 668387.7 | L37: =K37/J37 -> 20.989465 | M37: =L37-C$5 -> 1.3794654 | N37: =M37/C$2 -> 0.40132997 | Q37: a row 6 | R37: =C$8*C$7/2 -> 174.16 | S37: =S36+C$9 -> 9.9807 | T37: =R37*S37 -> 1738.2387 | U37: =U36+R37 -> 31843.96 | V37: =V36+T37 -> 652754.47 | W37: =V37/U37 -> 20.498533 | X37: =W37-C$5 -> 0.88853309 | Y37: =X37/C$2 -> 0.25850229
B38: All cells in green take their values from pay, load, stuff! | F38: a row 19 | G38: =C$8/2*C$7 -> 174.16 | H38: =H13 -> 20.2169 | I38: =G38*H38 -> 3520.9753 | J38: =J37+G38 -> 32018.12 | K38: =K37+I38 -> 671908.67 | L38: =K38/J38 -> 20.985263 | M38: =L38-C$5 -> 1.3752631 | N38: =M38/C$2 -> 0.40010739 | Q38: a row 7 | R38: =C$8*C$7/2 -> 174.16 | S38: =S37+C$9 -> 10.7681 | T38: =R38*S38 -> 1875.3723 | U38: =U37+R38 -> 32018.12 | V38: =V37+T38 -> 654629.84 | W38: =V38/U38 -> 20.445605 | X38: =W38-C$5 -> 0.83560518 | Y38: =X38/C$2 -> 0.24310389
F39: a row 18 | G39: =C$8/2*C$7 -> 174.16 | H39: =H14 -> 19.4295 | I39: =G39*H39 -> 3383.8417 | J39: =J38+G39 -> 32192.28 | K39: =K38+I39 -> 675292.51 | L39: =K39/J39 -> 20.976846 | M39: =L39-C$5 -> 1.3668464 | N39: =M39/C$2 -> 0.39765872 | Q39: a row 8 | R39: =C$8*C$7/2 -> 174.16 | S39: =S38+C$9 -> 11.5555 | T39: =R39*S39 -> 2012.5059 | U39: =U38+R39 -> 32192.28 | V39: =V38+T39 -> 656642.35 | W39: =V39/U39 -> 20.39751 | X39: =W39-C$5 -> 0.78750978 | Y39: =X39/C$2 -> 0.22911142
F40: a row 17 | G40: =C$8/2*C$7 -> 174.16 | H40: =H15 -> 18.6421 | I40: =G40*H40 -> 3246.7081 | J40: =J39+G40 -> 32366.44 | K40: =K39+I40 -> 678539.22 | L40: =K40/J40 -> 20.964283 | M40: =L40-C$5 -> 1.3542834 | N40: =M40/C$2 -> 0.39400375 | Q40: a row 9 | R40: =C$8*C$7/2 -> 174.16 | S40: =S39+C$9 -> 12.3429 | T40: =R40*S40 -> 2149.6395 | U40: =U39+R40 -> 32366.44 | V40: =V39+T40 -> 658791.99 | W40: =V40/U40 -> 20.354169 | X40: =W40-C$5 -> 0.74416887 | Y40: =X40/C$2 -> 0.21650219
F41: a row 16 | G41: =C$8/2*C$7 -> 174.16 | H41: =H16 -> 17.8547 | I41: =G41*H41 -> 3109.5746 | J41: =J40+G41 -> 32540.6 | K41: =K40+I41 -> 681648.8 | L41: =K41/J41 -> 20.947641 | M41: =L41-C$5 -> 1.3376407 | N41: =M41/C$2 -> 0.38916184 | Q41: a row 10 | R41: =C$8*C$7/2 -> 174.16 | S41: =S40+C$9 -> 13.1303 | T41: =R41*S41 -> 2286.773 | U41: =U40+R41 -> 32540.6 | V41: =V40+T41 -> 661078.76 | W41: =V41/U41 -> 20.315506 | X41: =W41-C$5 -> 0.70550612 | Y41: =X41/C$2 -> 0.20525397
...

Sheet CRJ-EXX Loading Diagram
B2: MAC | C2: =cg_loading_exx!F5 -> 3.4372349
B3: lf | C3: ='CRJ-1000 Loading Diagram'!C3 -> 36.57 | G3: mass [kg] | H3: x_front [m] | I3: moment [kg*m] | J3: mass total [kg] | K3: moment total [kg*m] | L3: xcg_nose [m] | M3: xcg_lemac [m] | N3: xcg_lemac_mac [-] | R3: mass [kg] | S3: x_front [m] | T3: moment [kg*m] | U3: mass total [kg] | V3: moment total [kg*m] | W3: xcg_nose [m] | X3: xcg_lemac [m] | Y3: xcg_lemac_mac [-]
B4: x_LEMAC/lf | C4: ='CRJ-1000 Loading Diagram'!C4 -> 0.53623188 | F4: OEW | G4: =cg_loading_exx!B68 -> 22490.463 | H4: =cg_loading_exx!C26 -> 21.498937 | I4: =G4*H4 -> 483521.05 | J4: =G4 -> 22490.463 | K4: =I4 -> 483521.05 | L4: =K4/J4 -> 21.498937 | M4: =L4-C$5 -> 1.888937 | N4: =M4/C$2 -> 0.54955132 | Q4: OEW | R4: =G4 -> 22490.463 | S4: =H4 -> 21.498937 | T4: =R4*S4 -> 483521.05 | U4: =R4 -> 22490.463 | V4: =T4 -> 483521.05 | W4: =V4/U4 -> 21.498937 | X4: =W4-C$5 -> 1.888937 | Y4: =X4/C$2 -> 0.54955132
B5: x_LEMAC | C5: =C3*C4 -> 19.61 | F5: OEW + Batt | G5: =G4+'Weight Pie Charts'!$D$41+'Weight Pie Charts'!$D$42 -> 26990.463 | H5: =cg_loading_exx!C34 -> 21.46658 | I5: =G5*H5 -> 579392.93 | J5: =G5 -> 26990.463 | K5: =I5 -> 579392.93 | L5: =K5/J5 -> 21.46658 | M5: =L5-C$5 -> 1.8565798 | N5: =M5/C$2 -> 0.54013761 | Q5: OEW + Batt | R5: =G5 -> 26990.463 | S5: =H5 -> 21.46658 | T5: =R5*S5 -> 579392.93 | U5: =R5 -> 26990.463 | V5: =T5 -> 579392.93 | W5: =V5/U5 -> 21.46658 | X5: =W5-C$5 -> 1.8565798 | Y5: =X5/C$2 -> 0.54013761
E6: cargo | F6: cargo aft | G6: ='Weight Pie Charts'!D43 -> 2487.9052 | H6: =cg_loading_exx!G62 -> 28.912942 | I6: =G6*H6 -> 71932.659 | J6: =J5+G6 -> 29478.368 | K6: =K5+I6 -> 651325.59 | L6: =K6/J6 -> 22.095035 | M6: =L6-C$5 -> 2.4850354 | N6: =M6/C$2 -> 0.72297514 | Q6: cargo front | R6: =G7 -> 769.09481 | S6: 11.31 | T6: =R6*S6 -> 8698.4623 | U6: =U5+R6 -> 27759.558 | V6: =V5+T6 -> 588091.39 | W6: =V6/U6 -> 21.185186 | X6: =W6-C$5 -> 1.5751858 | Y6: =X6/C$2 -> 0.45827122
B7: Standard person mass | C7: ='CRJ-1000 Loading Diagram'!C7 -> 87.08 | F7: cargo front | G7: ='Weight Pie Charts'!D44 -> 769.09481 | H7: =cg_loading_exx!G60 -> 11.446654 | I7: =G7*H7 -> 8803.5622 | J7: =J6+G7 -> 30247.463 | K7: =K6+I7 -> 660129.15 | L7: =K7/J7 -> 21.824282 | M7: =L7-C$5 -> 2.2142816 | N7: =M7/C$2 -> 0.64420433 | Q7: cargo aft | R7: =G6 -> 2487.9052 | S7: 28.6 | T7: =R7*S7 -> 71154.088 | U7: =U6+R7 -> 30247.463 | V7: =V6+T7 -> 659245.48 | W7: =V7/U7 -> 21.795067 | X7: =W7-C$5 -> 2.1850669 | Y7: =X7/C$2 -> 0.63570485
B8: pax per row | C8: 4 | E8: back to front | F8: w row 22 | G8: =C$8/2*C$7 -> 174.16 | H8: ='CRJ-1000 Loading Diagram'!H7-3*C9 -> 22.5791 | I8: =G8*H8 -> 3932.3761 | J8: =J7+G8 -> 30421.623 | K8: =K7+I8 -> 664061.52 | L8: =K8/J8 -> 21.828603 | M8: =L8-C$5 -> 2.2186028 | N8: =M8/C$2 -> 0.64546151 | P8: front to back | Q8: w row 1 | R8: =C$8*C$7/2 -> 174.16 | S8: ='CRJ-1000 Loading Diagram'!S7 -> 6.0437 | T8: =R8*S8 -> 1052.5708 | U8: =U7+R8 -> 30421.623 | V8: =V7+T8 -> 660298.05 | W8: =V8/U8 -> 21.704892 | X8: =W8-C$5 -> 2.0948923 | Y8: =X8/C$2 -> 0.60947021
B9: seat pitch [m] | C9: =31*0.0254 -> 0.7874 | F9: w row 21 | G9: =C$8/2*C$7 -> 174.16 | H9: =H8-C$9 -> 21.7917 | I9: =G9*H9 -> 3795.2425 | J9: =J8+G9 -> 30595.783 | K9: =K8+I9 -> 667856.77 | L9: =K9/J9 -> 21.828393 | M9: =L9-C$5 -> 2.2183928 | N9: =M9/C$2 -> 0.6454004 | Q9: w row 2 | R9: =C$8*C$7/2 -> 174.16 | S9: =S8+C$9 -> 6.8311 | T9: =R9*S9 -> 1189.7044 | U9: =U8+R9 -> 30595.783 | V9: =V8+T9 -> 661487.75 | W9: =V9/U9 -> 21.620226 | X9: =W9-C$5 -> 2.0102264 | Y9: =X9/C$2 -> 0.58483823
F10: w row 20 | G10: =C$8/2*C$7 -> 174.16 | H10: =H9-C$9 -> 21.0043 | I10: =G10*H10 -> 3658.1089 | J10: =J9+G10 -> 30769.943 | K10: =K9+I10 -> 671514.88 | L10: =K10/J10 -> 21.823728 | M10: =L10-C$5 -> 2.2137284 | N10: =M10/C$2 -> 0.64404337 | Q10: w row 3 | R10: =C$8*C$7/2 -> 174.16 | S10: =S9+C$9 -> 7.6185 | T10: =R10*S10 -> 1326.838 | U10: =U9+R10 -> 30769.943 | V10: =V9+T10 -> 662814.59 | W10: =V10/U10 -> 21.540976 | X10: =W10-C$5 -> 1.9309756 | Y10: =X10/C$2 -> 0.56178169
B11: This is an Excel Sheet made for the loading (potato) diagram of our modified CRJ-EXX. It mostly takes values from the CRJ-1000 Loading Diagram and Weight Pie Charts, but also MAC and x_LEMAC from cg_loading | F11: w row 19 | G11: =C$8/2*C$7 -> 174.16 | H11: =H10-C$9 -> 20.2169 | I11: =G11*H11 -> 3520.9753 | J11: =J10+G11 -> 30944.103 | K11: =K10+I11 -> 675035.85 | L11: =K11/J11 -> 21.814685 | M11: =L11-C$5 -> 2.2046848 | N11: =M11/C$2 -> 0.64141231 | Q11: w row 4 | R11: =C$8*C$7/2 -> 174.16 | S11: =S10+C$9 -> 8.4059 | T11: =R11*S11 -> 1463.9715 | U11: =U10+R11 -> 30944.103 | V11: =V10+T11 -> 664278.56 | W11: =V11/U11 -> 21.467049 | X11: =W11-C$5 -> 1.8570486 | Y11: =X11/C$2 -> 0.540274
F12: w row 18 | G12: =C$8/2*C$7 -> 174.16 | H12: =H11-C$9 -> 19.4295 | I12: =G12*H12 -> 3383.8417 | J12: =J11+G12 -> 31118.263 | K12: =K11+I12 -> 678419.69 | L12: =K12/J12 -> 21.801336 | M12: =L12-C$5 -> 2.1913356 | N12: =M12/C$2 -> 0.63752861 | Q12: w row 5 | R12: =C$8*C$7/2 -> 174.16 | S12: =S11+C$9 -> 9.1933 | T12: =R12*S12 -> 1601.1051 | U12: =U11+R12 -> 31118.263 | V12: =V11+T12 -> 665879.67 | W12: =V12/U12 -> 21.398356 | X12: =W12-C$5 -> 1.788356 | Y12: =X12/C$2 -> 0.52028914
F13: w row 17 | G13: =C$8/2*C$7 -> 174.16 | H13: =H12-C$9 -> 18.6421 | I13: =G13*H13 -> 3246.7081 | J13: =J12+G13 -> 31292.423 | K13: =K12+I13 -> 681666.4 | L13: =K13/J13 -> 21.783753 | M13: =L13-C$5 -> 2.1737527 | N13: =M13/C$2 -> 0.63241318 | Q13: w row 6 | R13: =C$8*C$7/2 -> 174.16 | S13: =S12+C$9 -> 9.9807 | T13: =R13*S13 -> 1738.2387 | U13: =U12+R13 -> 31292.423 | V13: =V12+T13 -> 667617.91 | W13: =V13/U13 -> 21.33481 | X13: =W13-C$5 -> 1.7248103 | Y13: =X13/C$2 -> 0.50180169
F14: w row 16 | G14: =C$8/2*C$7 -> 174.16 | H14: =H13-C$9 -> 17.8547 | I14: =G14*H14 -> 3109.5746 | J14: =J13+G14 -> 31466.583 | K14: =K13+I14 -> 684775.98 | L14: =K14/J14 -> 21.762006 | M14: =L14-C$5 -> 2.1520063 | N14: =M14/C$2 -> 0.62608648 | Q14: w row 7 | R14: =C$8*C$7/2 -> 174.16 | S14: =S13+C$9 -> 10.7681 | T14: =R14*S14 -> 1875.3723 | U14: =U13+R14 -> 31466.583 | V14: =V13+T14 -> 669493.28 | W14: =V14/U14 -> 21.276326 | X14: =W14-C$5 -> 1.6663261 | Y14: =X14/C$2 -> 0.48478679
F15: w row 15 | G15: =C$8/2*C$7 -> 174.16 | H15: =H14-C$9 -> 17.0673 | I15: =G15*H15 -> 2972.441 | J15: =J14+G15 -> 31640.743 | K15: =K14+I15 -> 687748.42 | L15: =K15/J15 -> 21.736165 | M15: =L15-C$5 -> 2.1261652 | N15: =M15/C$2 -> 0.6185685 | Q15: w row 8 | R15: =C$8*C$7/2 -> 174.16 | S15: =S14+C$9 -> 11.5555 | T15: =R15*S15 -> 2012.5059 | U15: =U14+R15 -> 31640.743 | V15: =V14+T15 -> 671505.78 | W15: =V15/U15 -> 21.22282 | X15: =W15-C$5 -> 1.6128198 | Y15: =X15/C$2 -> 0.46922012
F16: w row 14 | G16: =C$8/2*C$7 -> 174.16 | H16: =H15-C$9 -> 16.2799 | I16: =G16*H16 -> 2835.3074 | J16: =J15+G16 -> 31814.903 | K16: =K15+I16 -> 690583.72 | L16: =K16/J16 -> 21.706297 | M16: =L16-C$5 -> 2.0962968 | N16: =M16/C$2 -> 0.60987882 | Q16: w row 9 | R16: =C$8*C$7/2 -> 174.16 | S16: =S15+C$9 -> 12.3429 | T16: =R16*S16 -> 2149.6395 | U16: =U15+R16 -> 31814.903 | V16: =V15+T16 -> 673655.42 | W16: =V16/U16 -> 21.17421 | X16: =W16-C$5 -> 1.5642096 | Y16: =X16/C$2 -> 0.4550779
F17: w row 13 | G17: =C$8/2*C$7 -> 174.16 | H17: =H16-C$9 -> 15.4925 | I17: =G17*H17 -> 2698.1738 | J17: =J16+G17 -> 31989.063 | K17: =K16+I17 -> 693281.9 | L17: =K17/J17 -> 21.672467 | M17: =L17-C$5 -> 2.0624666 | N17: =M17/C$2 -> 0.60003656 | Q17: w row 10 | R17: =C$8*C$7/2 -> 174.16 | S17: =S16+C$9 -> 13.1303 | T17: =R17*S17 -> 2286.773 | U17: =U16+R17 -> 31989.063 | V17: =V16+T17 -> 675942.2 | W17: =V17/U17 -> 21.130416 | X17: =W17-C$5 -> 1.5204157 | Y17: =X17/C$2 -> 0.44233686
F18: w row 12 | G18: =C$8/2*C$7 -> 174.16 | H18: =H17-C$9 -> 14.7051 | I18: =G18*H18 -> 2561.0402 | J18: =J17+G18 -> 32163.223 | K18: =K17+I18 -> 695842.94 | L18: =K18/J18 -> 21.634739 | M18: =L18-C$5 -> 2.0247391 | N18: =M18/C$2 -> 0.58906045 | Q18: w row 11 | R18: =C$8*C$7/2 -> 174.16 | S18: =S17+C$9 -> 13.9177 | T18: =R18*S18 -> 2423.9066 | U18: =U17+R18 -> 32163.223 | V18: =V17+T18 -> 678366.1 | W18: =V18/U18 -> 21.09136 | X18: =W18-C$5 -> 1.4813597 | Y18: =X18/C$2 -> 0.43097424
F19: w row 11 | G19: =C$8/2*C$7 -> 174.16 | H19: =H18-C$9 -> 13.9177 | I19: =G19*H19 -> 2423.9066 | J19: =J18+G19 -> 32337.383 | K19: =K18+I19 -> 698266.84 | L19: =K19/J19 -> 21.593177 | M19: =L19-C$5 -> 1.9831774 | N19: =M19/C$2 -> 0.57696882 | Q19: w row 12 | R19: =C$8*C$7/2 -> 174.16 | S19: =S18+C$9 -> 14.7051 | T19: =R19*S19 -> 2561.0402 | U19: =U18+R19 -> 32337.383 | V19: =V18+T19 -> 680927.14 | W19: =V19/U19 -> 21.056965 | X19: =W19-C$5 -> 1.4469651 | Y19: =X19/C$2 -> 0.42096777
B20: 29.03.2026: I still don't have the OEW of the modified AC, as well as its x_cg, on top of the things that are still not correct for CRJ-1000 potato diagram. | F20: w row 10 | G20: =C$8/2*C$7 -> 174.16 | H20: =H19-C$9 -> 13.1303 | I20: =G20*H20 -> 2286.773 | J20: =J19+G20 -> 32511.543 | K20: =K19+I20 -> 700553.62 | L20: =K20/J20 -> 21.547843 | M20: =L20-C$5 -> 1.9378428 | N20: =M20/C$2 -> 0.56377958 | Q20: w row 13 | R20: =C$8*C$7/2 -> 174.16 | S20: =S19+C$9 -> 15.4925 | T20: =R20*S20 -> 2698.1738 | U20: =U19+R20 -> 32511.543 | V20: =V19+T20 -> 683625.32 | W20: =V20/U20 -> 21.027157 | X20: =W20-C$5 -> 1.417157 | Y20: =X20/C$2 -> 0.41229565
F21: w row 9 | G21: =C$8/2*C$7 -> 174.16 | H21: =H20-C$9 -> 12.3429 | I21: =G21*H21 -> 2149.6395 | J21: =J20+G21 -> 32685.703 | K21: =K20+I21 -> 702703.26 | L21: =K21/J21 -> 21.498796 | M21: =L21-C$5 -> 1.8887959 | N21: =M21/C$2 -> 0.54951029 | Q21: w row 14 | R21: =C$8*C$7/2 -> 174.16 | S21: =S20+C$9 -> 16.2799 | T21: =R21*S21 -> 2835.3074 | U21: =U20+R21 -> 32685.703 | V21: =V20+T21 -> 686460.63 | W21: =V21/U21 -> 21.001862 | X21: =W21-C$5 -> 1.3918621 | Y21: =X21/C$2 -> 0.40493656
F22: w row 8 | G22: =C$8/2*C$7 -> 174.16 | H22: =H21-C$9 -> 11.5555 | I22: =G22*H22 -> 2012.5059 | J22: =J21+G22 -> 32859.863 | K22: =K21+I22 -> 704715.76 | L22: =K22/J22 -> 21.446096 | M22: =L22-C$5 -> 1.8360956 | N22: =M22/C$2 -> 0.53417811 | Q22: w row 15 | R22: =C$8*C$7/2 -> 174.16 | S22: =S21+C$9 -> 17.0673 | T22: =R22*S22 -> 2972.441 | U22: =U21+R22 -> 32859.863 | V22: =V21+T22 -> 689433.07 | W22: =V22/U22 -> 20.981009 | X22: =W22-C$5 -> 1.3710086 | Y22: =X22/C$2 -> 0.39886962
F23: w row 7 | G23: =C$8/2*C$7 -> 174.16 | H23: =H22-C$9 -> 10.7681 | I23: =G23*H23 -> 1875.3723 | J23: =J22+G23 -> 33034.023 | K23: =K22+I23 -> 706591.14 | L23: =K23/J23 -> 21.3898 | M23: =L23-C$5 -> 1.7797998 | N23: =M23/C$2 -> 0.51779986 | Q23: w row 16 | R23: =C$8*C$7/2 -> 174.16 | S23: =S22+C$9 -> 17.8547 | T23: =R23*S23 -> 3109.5746 | U23: =U22+R23 -> 33034.023 | V23: =V22+T23 -> 692542.64 | W23: =V23/U23 -> 20.964526 | X23: =W23-C$5 -> 1.3545262 | Y23: =X23/C$2 -> 0.39407439
F24: w row 6 | G24: =C$8/2*C$7 -> 174.16 | H24: =H23-C$9 -> 9.9807 | I24: =G24*H24 -> 1738.2387 | J24: =J23+G24 -> 33208.183 | K24: =K23+I24 -> 708329.37 | L24: =K24/J24 -> 21.329965 | M24: =L24-C$5 -> 1.7199648 | N24: =M24/C$2 -> 0.500392 | Q24: w row 17 | R24: =C$8*C$7/2 -> 174.16 | S24: =S23+C$9 -> 18.6421 | T24: =R24*S24 -> 3246.7081 | U24: =U23+R24 -> 33208.183 | V24: =V23+T24 -> 695789.35 | W24: =V24/U24 -> 20.952346 | X24: =W24-C$5 -> 1.3423463 | Y24: =X24/C$2 -> 0.39053086
F25: w row 5 | G25: =C$8/2*C$7 -> 174.16 | H25: =H24-C$9 -> 9.1933 | I25: =G25*H25 -> 1601.1051 | J25: =J24+G25 -> 33382.343 | K25: =K24+I25 -> 709930.48 | L25: =K25/J25 -> 21.266646 | M25: =L25-C$5 -> 1.6566463 | N25: =M25/C$2 -> 0.48197064 | Q25: w row 18 | R25: =C$8*C$7/2 -> 174.16 | S25: =S24+C$9 -> 19.4295 | T25: =R25*S25 -> 3383.8417 | U25: =U24+R25 -> 33382.343 | V25: =V24+T25 -> 699173.19 | W25: =V25/U25 -> 20.944401 | X25: =W25-C$5 -> 1.3344014 | Y25: =X25/C$2 -> 0.38821944
F26: w row 4 | G26: =C$8/2*C$7 -> 174.16 | H26: =H25-C$9 -> 8.4059 | I26: =G26*H26 -> 1463.9715 | J26: =J25+G26 -> 33556.503 | K26: =K25+I26 -> 711394.45 | L26: =K26/J26 -> 21.199898 | M26: =L26-C$5 -> 1.5898983 | N26: =M26/C$2 -> 0.46255155 | Q26: w row 19 | R26: =C$8*C$7/2 -> 174.16 | S26: =S25+C$9 -> 20.2169 | T26: =R26*S26 -> 3520.9753 | U26: =U25+R26 -> 33556.503 | V26: =V25+T26 -> 702694.17 | W26: =V26/U26 -> 20.940626 | X26: =W26-C$5 -> 1.3306256 | Y26: =X26/C$2 -> 0.38712095
F27: w row 3 | G27: =C$8/2*C$7 -> 174.16 | H27: =H26-C$9 -> 7.6185 | I27: =G27*H27 -> 1326.838 | J27: =J26+G27 -> 33730.663 | K27: =K26+I27 -> 712721.29 | L27: =K27/J27 -> 21.129774 | M27: =L27-C$5 -> 1.5197741 | N27: =M27/C$2 -> 0.44215021 | Q27: w row 20 | R27: =C$8*C$7/2 -> 174.16 | S27: =S26+C$9 -> 21.0043 | T27: =R27*S27 -> 3658.1089 | U27: =U26+R27 -> 33730.663 | V27: =V26+T27 -> 706352.27 | W27: =V27/U27 -> 20.940954 | X27: =W27-C$5 -> 1.3309544 | Y27: =X27/C$2 -> 0.3872166
B28: All cells in yellow have values that need to be calculated manually, the ones you see for now were (poorly) eyeballed! | F28: w row 2 | G28: =C$8/2*C$7 -> 174.16 | H28: =H27-C$9 -> 6.8311 | I28: =G28*H28 -> 1189.7044 | J28: =J27+G28 -> 33904.823 | K28: =K27+I28 -> 713910.99 | L28: =K28/J28 -> 21.056326 | M28: =L28-C$5 -> 1.4463257 | N28: =M28/C$2 -> 0.42078174 | Q28: w row 21 | R28: =C$8*C$7/2 -> 174.16 | S28: =S27+C$9 -> 21.7917 | T28: =R28*S28 -> 3795.2425 | U28: =U27+R28 -> 33904.823 | V28: =V27+T28 -> 710147.52 | W28: =V28/U28 -> 20.945324 | X28: =W28-C$5 -> 1.3353245 | Y28: =X28/C$2 -> 0.38848799
F29: w row 1 | G29: =C$8/2*C$7 -> 174.16 | H29: =H28-C$9 -> 6.0437 | I29: =G29*H29 -> 1052.5708 | J29: =J28+G29 -> 34078.983 | K29: =K28+I29 -> 714963.56 | L29: =K29/J29 -> 20.979604 | M29: =L29-C$5 -> 1.3696039 | N29: =M29/C$2 -> 0.39846096 | Q29: w row 22 | R29: =C$8*C$7/2 -> 174.16 | S29: =S28+C$9 -> 22.5791 | T29: =R29*S29 -> 3932.3761 | U29: =U28+R29 -> 34078.983 | V29: =V28+T29 -> 714079.89 | W29: =V29/U29 -> 20.953674 | X29: =W29-C$5 -> 1.3436738 | Y29: =X29/C$2 -> 0.39091708
F30: a row 22 | G30: =C$8/2*C$7 -> 174.16 | H30: =H8 -> 22.5791 | I30: =G30*H30 -> 3932.3761 | J30: =J29+G30 -> 34253.143 | K30: =K29+I30 -> 718895.94 | L30: =K30/J30 -> 20.987737 | M30: =L30-C$5 -> 1.3777366 | N30: =M30/C$2 -> 0.400827 | Q30: a row 1 | R30: =C$8*C$7/2 -> 174.16 | S30: =S8 -> 6.0437 | T30: =R30*S30 -> 1052.5708 | U30: =U29+R30 -> 34253.143 | V30: =V29+T30 -> 715132.46 | W30: =V30/U30 -> 20.877864 | X30: =W30-C$5 -> 1.2678641 | Y30: =X30/C$2 -> 0.36886165
B31: The values have now been somewhat improved | F31: a row 21 | G31: =C$8/2*C$7 -> 174.16 | H31: =H9 -> 21.7917 | I31: =G31*H31 -> 3795.2425 | J31: =J30+G31 -> 34427.303 | K31: =K30+I31 -> 722691.18 | L31: =K31/J31 -> 20.991804 | M31: =L31-C$5 -> 1.3818036 | N31: =M31/C$2 -> 0.40201024 | Q31: a row 2 | R31: =C$8*C$7/2 -> 174.16 | S31: =S30+C$9 -> 6.8311 | T31: =R31*S31 -> 1189.7044 | U31: =U30+R31 -> 34427.303 | V31: =V30+T31 -> 716322.17 | W31: =V31/U31 -> 20.806805 | X31: =W31-C$5 -> 1.1968047 | Y31: =X31/C$2 -> 0.34818822
B32: All cells in pink take their values from cg_loading_exx! | F32: a row 20 | G32: =C$8/2*C$7 -> 174.16 | H32: =H10 -> 21.0043 | I32: =G32*H32 -> 3658.1089 | J32: =J31+G32 -> 34601.463 | K32: =K31+I32 -> 726349.29 | L32: =K32/J32 -> 20.991867 | M32: =L32-C$5 -> 1.3818665 | N32: =M32/C$2 -> 0.40202854 | Q32: a row 3 | R32: =C$8*C$7/2 -> 174.16 | S32: =S31+C$9 -> 7.6185 | T32: =S32*R32 -> 1326.838 | U32: =U31+R32 -> 34601.463 | V32: =V31+T32 -> 717649.01 | W32: =V32/U32 -> 20.740424 | X32: =W32-C$5 -> 1.1304238 | Y32: =X32/C$2 -> 0.32887593
F33: a row 19 | G33: =C$8/2*C$7 -> 174.16 | H33: =H11 -> 20.2169 | I33: =G33*H33 -> 3520.9753 | J33: =J32+G33 -> 34775.623 | K33: =K32+I33 -> 729870.27 | L33: =K33/J33 -> 20.987985 | M33: =L33-C$5 -> 1.3779854 | N33: =M33/C$2 -> 0.4008994 | Q33: a row 4 | R33: =C$8*C$7/2 -> 174.16 | S33: =S32+C$9 -> 8.4059 | T33: =S33*R33 -> 1463.9715 | U33: =U32+R33 -> 34775.623 | V33: =V32+T33 -> 719112.98 | W33: =V33/U33 -> 20.678651 | X33: =W33-C$5 -> 1.0686512 | Y33: =X33/C$2 -> 0.31090433
B34: pink??? | F34: a row 18 | G34: =C$8/2*C$7 -> 174.16 | H34: =H12 -> 19.4295 | I34: =G34*H34 -> 3383.8417 | J34: =J33+G34 -> 34949.783 | K34: =K33+I34 -> 733254.11 | L34: =K34/J34 -> 20.980219 | M34: =L34-C$5 -> 1.3702192 | N34: =M34/C$2 -> 0.39863998 | Q34: a row 5 | R34: =C$8*C$7/2 -> 174.16 | S34: =S33+C$9 -> 9.1933 | T34: =S34*R34 -> 1601.1051 | U34: =U33+R34 -> 34949.783 | V34: =V33+T34 -> 720714.08 | W34: =V34/U34 -> 20.621418 | X34: =W34-C$5 -> 1.011418 | Y34: =X34/C$2 -> 0.29425338
B35: All cells in blue take their values from Weight Pie Chart! | F35: a row 17 | G35: =C$8/2*C$7 -> 174.16 | H35: =H13 -> 18.6421 | I35: =G35*H35 -> 3246.7081 | J35: =J34+G35 -> 35123.943 | K35: =K34+I35 -> 736500.82 | L35: =K35/J35 -> 20.968626 | M35: =L35-C$5 -> 1.3586258 | N35: =M35/C$2 -> 0.39526709 | Q35: a row 6 | R35: =C$8*C$7/2 -> 174.16 | S35: =S34+C$9 -> 9.9807 | T35: =S35*R35 -> 1738.2387 | U35: =U34+R35 -> 35123.943 | V35: =V34+T35 -> 722452.32 | W35: =V35/U35 -> 20.568657 | X35: =W35-C$5 -> 0.95865663 | Y35: =X35/C$2 -> 0.27890344
F36: a row 16 | G36: =C$8/2*C$7 -> 174.16 | H36: =H14 -> 17.8547 | I36: =G36*H36 -> 3109.5746 | J36: =J35+G36 -> 35298.103 | K36: =K35+I36 -> 739610.39 | L36: =K36/J36 -> 20.953262 | M36: =L36-C$5 -> 1.3432618 | N36: =M36/C$2 -> 0.3907972 | Q36: a row 7 | R36: =C$8*C$7/2 -> 174.16 | S36: =S35+C$9 -> 10.7681 | T36: =S36*R36 -> 1875.3723 | U36: =U35+R36 -> 35298.103 | V36: =V35+T36 -> 724327.69 | W36: =V36/U36 -> 20.520301 | X36: =W36-C$5 -> 0.91030092 | Y36: =X36/C$2 -> 0.26483524
F37: a row 15 | G37: =C$8/2*C$7 -> 174.16 | H37: =H15 -> 17.0673 | I37: =G37*H37 -> 2972.441 | J37: =J36+G37 -> 35472.263 | K37: =K36+I37 -> 742582.83 | L37: =K37/J37 -> 20.934183 | M37: =L37-C$5 -> 1.3241827 | N37: =M37/C$2 -> 0.38524649 | Q37: a row 8 | R37: =C$8*C$7/2 -> 174.16 | S37: =S36+C$9 -> 11.5555 | T37: =S37*R37 -> 2012.5059 | U37: =U36+R37 -> 35472.263 | V37: =V36+T37 -> 726340.2 | W37: =V37/U37 -> 20.476286 | X37: =W37-C$5 -> 0.86628597 | Y37: =X37/C$2 -> 0.2520299
F38: a row 14 | G38: =C$8/2*C$7 -> 174.16 | H38: =H16 -> 16.2799 | I38: =G38*H38 -> 2835.3074 | J38: =J37+G38 -> 35646.423 | K38: =K37+I38 -> 745418.14 | L38: =K38/J38 -> 20.911443 | M38: =L38-C$5 -> 1.301443 | N38: =M38/C$2 -> 0.37863079 | Q38: a row 9 | R38: =C$8*C$7/2 -> 174.16 | S38: =S37+C$9 -> 12.3429 | T38: =S38*R38 -> 2149.6395 | U38: =U37+R38 -> 35646.423 | V38: =V37+T38 -> 728489.84 | W38: =V38/U38 -> 20.436548 | X38: =W38-C$5 -> 0.82654817 | Y38: =X38/C$2 -> 0.24046892
B39: Important note! Since the battery is non-removable (and we don't want to calculate the cg's for the batteries separately), this loading diagram just assumes they are loaded in one go. | F39: a row 13 | G39: =C$8/2*C$7 -> 174.16 | H39: =H17 -> 15.4925 | I39: =G39*H39 -> 2698.1738 | J39: =J38+G39 -> 35820.583 | K39: =K38+I39 -> 748116.31 | L39: =K39/J39 -> 20.885096 | M39: =L39-C$5 -> 1.275096 | N39: =M39/C$2 -> 0.37096563 | Q39: a row 10 | R39: =C$8*C$7/2 -> 174.16 | S39: =S38+C$9 -> 13.1303 | T39: =S39*R39 -> 2286.773 | U39: =U38+R39 -> 35820.583 | V39: =V38+T39 -> 730776.61 | W39: =V39/U39 -> 20.401025 | X39: =W39-C$5 -> 0.79102512 | Y39: =X39/C$2 -> 0.23013415
F40: a row 12 | G40: =C$8/2*C$7 -> 174.16 | H40: =H18 -> 14.7051 | I40: =G40*H40 -> 2561.0402 | J40: =J39+G40 -> 35994.743 | K40: =K39+I40 -> 750677.35 | L40: =K40/J40 -> 20.855194 | M40: =L40-C$5 -> 1.2451942 | N40: =M40/C$2 -> 0.36226625 | Q40: a row 11 | R40: =C$8*C$7/2 -> 174.16 | S40: =S39+C$9 -> 13.9177 | T40: =S40*R40 -> 2423.9066 | U40: =U39+R40 -> 35994.743 | V40: =V39+T40 -> 733200.52 | W40: =V40/U40 -> 20.369656 | X40: =W40-C$5 -> 0.75965566 | Y40: =X40/C$2 -> 0.22100778
F41: a row 11 | G41: =C$8/2*C$7 -> 174.16 | H41: =H19 -> 13.9177 | I41: =G41*H41 -> 2423.9066 | J41: =J40+G41 -> 36168.903 | K41: =K40+I41 -> 753101.26 | L41: =K41/J41 -> 20.821789 | M41: =L41-C$5 -> 1.2117889 | N41: =M41/C$2 -> 0.35254758 | Q41: a row 12 | R41: =C$8*C$7/2 -> 174.16 | S41: =S40+C$9 -> 14.7051 | T41: =S41*R41 -> 2561.0402 | U41: =U40+R41 -> 36168.903 | V41: =V40+T41 -> 735761.56 | W41: =V41/U41 -> 20.34238 | X41: =W41-C$5 -> 0.73237977 | Y41: =X41/C$2 -> 0.21307236
...

Sheet CG Range
B3: CRJ-1000 | F3: CRJ-EXX
B5: x_LEMAC/lf | C5: min + 2% | D5: max + 2% | F5: x_LEMAC/lf | G5: min + 2% | H5: max + 2%
B6: ='CRJ-1000 Loading Diagram'!C4 -> 0.53623188 | C6: =MIN('CRJ-1000 Loading Diagram'!Y4:Y57)-0.02 -> 0.14175045 | D6: =MAX('CRJ-1000 Loading Diagram'!N4:N57)+0.02 -> 0.76959617 | F6: ='CRJ-EXX Loading Diagram'!C4 -> 0.53623188 | G6: =MIN('CRJ-EXX Loading Diagram'!Y4:Y52)-0.02 -> 0.16947306 | H6: =MAX('CRJ-EXX Loading Diagram'!N4:N52)+0.02 -> 0.74297514
B10: TO DO: Once the Loading Diagrams have all correct values, tweak the x_LEMAC/lf and write the resulting xmin and xmax in the tables below. Based on this, construct the cg range plot. THESE ARE TOTALLY NOT UP TO DATE
B14: x_LEMAC/lf | C14: min + 2% | D14: max + 2% | F14: x_LEMAC/lf | G14: min + 2% | H14: max + 2%
B15: 0.25 | C15: 1.652832 | D15: 2.158519 | F15: 0.25 | G15: 1.691696 | H15: 2.608029
B16: 0.35 | C16: 0.591921 | D16: 1.097608 | F16: 0.35 | G16: 0.630785 | H16: 1.547118
B17: 0.45 | C17: -0.46899 | D17: 0.036697 | F17: 0.45 | G17: -0.43013 | H17: 0.486207

Sheet Weight Pie Charts
C4: CRJ-1000
E6: % MTOW
C7: MTOW | D7: 41640 | E7: 100
C9: OEW | D9: 23188 | E9: =D9/D$7*100 -> 55.68684
C10: Wp (cabin) | D10: =D20 -> 8708 | E10: =D10/D$7*100 -> 20.912584
C11: WF | D11: =D7-D9-D18 -> 6487 | E11: =D11/D$7*100 -> 15.57877
C12: Wp (aft) | D12: =D27 -> 2386.0381 | E12: =D12/D$7*100 -> 5.7301588
C13: Wp (front) | D13: =D26 -> 870.96187 | E13: =D13/D$7*100 -> 2.0916471
C14: Total | D14: =SUM(D9:D13) -> 41640 | E14: =D14/D7*100 -> 100
C18: Wp | D18: 11965
C19: Wcargo | D19: 3257
C20: Wp cabin | D20: =D18-D19 -> 8708
C22: V front | D22: 5.26
C23: V aft | D23: 14.41
C24: V tot | D24: =D23+D22 -> 19.67
C26: W front | D26: =D22/D24*D19 -> 870.96187
C27: W aft | D27: =D23/D24*D19 -> 2386.0381
C28: Total | D28: =D27+D26 -> 3257
C33: CRJ-EXX
E35: % MTOW
C36: MTOW | D36: 41640 | E36: 100
C38: OEW | D38: =cg_loading_exx!B68 -> 22490.463 | E38: =D38/D$7*100 -> 54.011679
C39: Wp (cabin) | D39: =8708*0.88 -> 7663.04 | E39: =D39/D$7*100 -> 18.403074
C40: WF | D40: =D36-D49-D38-D42-D41 -> 3729.4971 | E40: =D40/D36*100 -> 8.9565251
C41: W Batt (front) | D41: =G55 -> 2025 | E41: =D41/D36*100 -> 4.8631124
C42: W Batt (aft) | D42: =G57 -> 2475 | E42: =D42/D36*100 -> 5.943804
C43: Wp (aft) | D43: =D59 -> 2487.9052 | E43: =D43/D$7*100 -> 5.9747963
C44: Wp (front) | D44: =D58 -> 769.09481 | E44: =D44/D$7*100 -> 1.8470096
C45: Total | D45: =SUM(D38:D44) -> 41640 | E45: =D45/D36*100 -> 100
E47: =E39+E43+E44 -> 26.22488
C49: Wp | D49: =D51+D50 -> 10920.04
C50: Wcargo | D50: 3257
C51: Wp cabin | D51: =D39 -> 7663.04
C53: New Cargo | F53: Battery
C54: V front | D54: =D22-G54 -> 3.96 | F54: V bat front | G54: 1.3
C55: V aft | D55: =D23-G56 -> 12.81 | F55: W bat front | G55: 2025
C56: V tot | D56: =D55+D54 -> 16.77 | F56: V bat aft | G56: 1.6
F57: W bat aft | G57: 2475
C58: W front | D58: =D54/D56*D50 -> 769.09481
C59: W aft | D59: =D55/D56*D50 -> 2487.9052
...

Sheet pay, load, stuff
D3: x_cargo_f | E3: x_cargo_a | F3: x_cabin | G3: sum | I3: x_payload
D4: 10.94 | E4: 29.15 | F4: 16.94 | I4: =SUM(D10:F10)/G7 -> 18.938083
D6: m_cargo_f | E6: m_cargo_a | F6: m_cabin
D7: 871 | E7: 2386 | F7: 8708 | G7: =SUM(D7:F7) -> 11965
D9: xm
D10: =D4*D7 -> 9528.74 | E10: =E4*E7 -> 69551.9 | F10: =F4*F7 -> 147513.52

Sheet DEPRECATED
L1: Control Curve | V1: X_cg / MAC | W1: Sh/S Stability | X1: Sh/S Control
B2: Stick fixed stability | L2: Gradient | M2: =1 / ( (P4/(P9)) *C37/C22 * C6 ) -> -0.40568246 | O2: Control curve | V2: 0 | W2: =$M$7*V2+$M$8 -> 0.078029313 | X2: =$M$2*W2+$M$3 -> 0.087281772
B3: Parameter | C3: Value | D3: Unit | F3: Description | L3: Intercept | M3: =(P5/(P9) - C4) / ( (P4/(P9)) *C37/C22 * C6 ) -> 0.1189369 | O3: Parameter | P3: Value | Q3: Unit | V3: 0.1 | W3: =$M$7*V3+$M$8 -> 0.12044196 | X3: =$M$2*W3+$M$3 -> 0.070075706
B4: x_ac | C4: =C17 - 1.8*C18*C19*C20/(C5*C21*C22) + 0.273*C18*C23*(C24-C18)*TAN(C26)/((1+C25)*C22^2*(C24+2.15*C18)) + 2*C27*C28^2*C29/(C21*C22*C5) -> 0.23397653 | D4: Fraction of MAC | E4: Slide No. 39-40 | F4: AC of the aircraft less tail | I4: Calculated | O4: C_Lh | P4: -1 | V4: =$V$3*2 -> 0.2 | W4: =$M$7*V4+$M$8 -> 0.1628546 | X4: =$M$2*W4+$M$3 -> 0.05286964
B5: C_LaA-h | C5: =C38*(1+2.15*C18/C24)*C35/C21+PI()*C18^2/(2*C21) -> 7.0250561 | D5: [rad^-1] | F5: Lift rate coeff. of the aircraft less tail | I5: Calculated | O5: C_m_ac | P5: -0.12 | V5: =$V$3*3 -> 0.3 | W5: =$M$7*V5+$M$8 -> 0.20526725 | X5: =$M$2*W5+$M$3 -> 0.035663573
B6: (V_h/V)^2 | C6: 1 | D6: N.A. | F6: Tail/wing speed ratio | I6: GIVEN | L6: Stability Curve | O6: alpha | P6: =10*PI()/180 -> 0.17453293 | Q6: rad | V6: =$V$3*4 -> 0.4 | W6: =$M$7*V6+$M$8 -> 0.24767989 | X6: =$M$2*W6+$M$3 -> 0.018457507
B7: C_Lah | C7: =(2*PI()*C30)/(2+SQRT(4+((C30*C34/C33)^2)*(1+(TAN(C31)^2)/(C34^2)))) -> 4.5133531 | D7: [rad^-1] | F7: Lift rate coeff of the aircraft's tail | I7: Calculated | L7: Gradient | M7: =1 / ( ( C7/C5)* ( 1 - C8 ) *(C37/C22) * ( C6 ) ) -> 0.42412645 | O7: C_LaA-h (approach) | P7: =C50*(1+2.15*C18/C24)*C35/C21+PI()*C18^2/(2*C21) -> 5.4348253 | V7: =$V$3*5 -> 0.5 | W7: =$M$7*V7+$M$8 -> 0.29009254 | X7: =$M$2*W7+$M$3 -> 0.0012514407
B8: de/da | C8: =(C44/C45) * ((C41/(C41^2+C42^2))*(0.4876/(SQRT(C41^2+0.6319+C42^2))) + (1 + (C41^2/(C41^2+0.7915+5.0734*C42^2))^0.3113)*(1 - SQRT(C42^2/(1+C42^2)))) * C38/(PI()*C39) -> 0.26550709 | D8: N.A. | E8: Slide No. 47 (hidden) | F8: Downwash effect | I8: Calculated | L8: Intercept | M8: =( C4 - C9 ) / ( ( C7/C5)* ( 1 - C8 ) *(C37/C22) * ( C6 ) ) -> 0.078029313 | O8: C_Law approach | P8: =C50 -> 4.5272184 | V8: =$V$3*6 -> 0.6 | W8: =$M$7*V8+$M$8 -> 0.33250518 | X8: =$M$2*W8+$M$3 -> -0.015954626
B9: SM | C9: 0.05 | D9: N.A. | F9: Safety margin | I9: GIVEN | O9: C_LA-h | P9: 2.027 | V9: =$V$3*7 -> 0.7 | W9: =$M$7*V9+$M$8 -> 0.37491783 | X9: =$M$2*W9+$M$3 -> -0.033160692
B10: C_Lh | C10: -1 | F10: maximum for movable tails | I10: Assumed | P10: 2.118 | V10: =$V$3*8 -> 0.8 | W10: =$M$7*V10+$M$8 -> 0.41733048 | X10: =$M$2*W10+$M$3 -> -0.050366758
B11: C_m_ac | C11: -0.12 | F11: from graph | I11: Assumed | P11: 2.4 | V11: =$V$3*9 -> 0.9 | W11: =$M$7*V11+$M$8 -> 0.45974312 | X11: =$M$2*W11+$M$3 -> -0.067572824
B12: alpha | C12: =10*PI()/180 -> 0.17453293 | D12: rad | F12: Assumed landing glide angle of attack | V12: 1 | W12: =$M$7*V12+$M$8 -> 0.50215577 | X12: =$M$2*W12+$M$3 -> -0.084778891
B15: Geometric and aero parameters
B16: Parameter | C16: Value | D16: Unit | F16: Description
B17: x_ac_w | C17: 0.35 | D17: Fraction of MAC | F17: Wing AC contribution | I17: General knowledge
B18: b_f | C18: 2.695 | D18: [m] | F18: Fuselage width | I18: From APM
B19: h_f | C19: 2.695 | D19: [m] | F19: Fuselage height | I19: From APM, assumption of circular fuselage, looks accurate (APM also specifies "diameter" so likely its round)
B20: l_fn | C20: 36.466 | D20: [m] | F20: Fuselage length | I20: From APM, but on ground, might be slightly different in flight
B21: S_w | C21: =(E60+E59)*C24/2 -> 80.845929 | D21: [m^2] | F21: Wing planform area | I21: From APM
B22: c_MAC | C22: =E61 -> 3.3863373 | D22: [m] | F22: MAC length | I22: We have a pixel calculation, but an actual one would be nicer
B23: c_g | C23: =C21/C24 -> 3.0886697 | D23: [m] | F23: Mean geometric chord | I23: From APM
B24: b | C24: 26.175 | D24: [m] | F24: Wing span | I24: From APM
B25: taper | C25: =E59/E60 -> 0.27960928 | D25: N.A. | F25: Wing taper | I25: Calculated
B26: c/4 sweep | C26: =ATAN(TAN(RADIANS(D62))-4*0.25*(1-C25)/(C39*(1+C25))) -> 0.46939193 | D26: [rad] | F26: Wing quarter chord sweep | I26: Calculated
B27: k_n | C27: -2.5 | D27: N.A. | F27: Nacelle contribution coeff. | I27: GIVEN
B28: b_n | C28: 1.55 | D28: [m] | F28: Nacelle width | I28: From APM, Actually height, but they seem circular
B29: l_n | C29: =E64 -> -11.874284 | D29: [m] | E29: Negative! (behind MAC/4) | F29: Nacelle position | I29: From APM 28.6 to front or 30.55 to center of nacelle. Actually, the value for front is to coinciding door, but seems close enough.
B30: A_h | C30: =((8.541)^2)/(15.91) -> 4.5850837 | D30: N.A. | F30: Tail aspect ratio | I30: Data from APM
B31: c/2 sweep_h | C31: =ATAN(TAN(RADIANS(D66))-4*0.5*(1-C43)/(C30*(1+C43))) -> 0.47262445 | D31: [rad] | F31: Tail half chord sweep | I31: Calculated
B32: M | C32: 0.78 | D32: N.A. | F32: Mach number | I32: Corporate contact
B33: eta | C33: 0.95 | D33: [-] | F33: Airfoil efficiency (lower bound taken) | I33: Conservative estimate
B34: beta | C34: =SQRT(1-(C32^2)) -> 0.62577951 | D34: [-] | I34: Calculated
B35: S_net | C35: 77.4 | D35: [m^2] | F35: Net wing area | I35: Corporate contact
B36: S_h | C36: 21.5 | D36: [m^2] | I36: Corporate contact
B37: l_h | C37: =E65 -> 16.919898 | D37: [m] | I37: Pixel measurements | K37: corporate contact: 13.5m
B38: C_Law | C38: =(2*PI()*C39)/(2+SQRT(4+((C39*C34/C33)^2)*(1+(TAN(C40)^2)/(C34^2)))) -> 5.8871955 | D38: [rad^-1] | I38: Calculated
B39: A_w | C39: =C24^2/C21 -> 8.4745223 | D39: [-] | I39: Calculated
B40: c/2 sweep_w | C40: =RADIANS(D63) -> 0.40299652 | D40: [rad] | I40: Pixel measurements
B41: r | C41: =E65/(C24/2) -> 1.2928288 | D41: [-] | I41: Calculated
B42: m_tv | C42: =E70/(C24/2) -> 0.51253762 | D42: [-] | I42: Calculated
...

Sheet Stability CRJ-EXX
B2: Stick fixed stability | L2: Control Curve Plot | O2: Control curve
B3: Parameter | C3: Value | D3: Unit | F3: Description | L3: Gradient | M3: =1 / ( (P4/(P9)) *C37/C22 * C6 ) -> -0.48681895 | O3: Parameter | P3: Value | Q3: Unit
B4: x_ac | C4: =C17 - 1.8*C18*C19*C20/(C5*C21*C22) + 0.273*C18*C23*(C24-C18)*TAN(C26)/((1+C25)*C22^2*(C24+2.15*C18)) + 2*C27*C28^2*C29/(C21*C22*C5) -> 0.28152097 | D4: Fraction of MAC | E4: Slide No. 39-40 | F4: AC of the aircraft less tail | I4: Calculated | L4: Intercept | M4: =(P5/(P9) - C4) / ( (P4/(P9)) *C37/C22 * C6 ) -> 0.22659907 | O4: C_Lh | P4: -1
B5: C_LaA-h | C5: =C38*(1+2.15*C18/C24)*C35/C21+PI()*C18^2/(2*C21) -> 7.4304072 | D5: [rad^-1] | F5: Lift rate coeff. of the aircraft less tail | I5: Calculated | O5: C_m_ac | P5: =C64 -> -0.4474349
B6: (V_h/V)^2 | C6: 1 | D6: N.A. | F6: Tail/wing speed ratio | I6: GIVEN | O6: alpha | P6: =10*PI()/180 -> 0.17453293 | Q6: rad
B7: C_Lah | C7: =(2*PI()*C30)/(2+SQRT(4+((C30*C34/C33)^2)*(1+(TAN(C31)^2)/(C34^2)))) -> 4.5133531 | D7: [rad^-1] | F7: Lift rate coeff of the aircraft's tail | I7: Calculated | L7: Stability Curve Plot | O7: C_LaA-h (approach) | P7: =C50*(1+2.15*C18/C24)*C35/C21+PI()*C18^2/(2*C21) -> 5.6571448
B8: de/da | C8: =(C44/C45) * ((C41/(C41^2+C42^2))*(0.4876/(SQRT(C41^2+0.6319+C42^2))) + (1 + (C41^2/(C41^2+0.7915+5.0734*C42^2))^0.3113)*(1 - SQRT(C42^2/(1+C42^2)))) * C38/(PI()*C39) -> 0.22510155 | D8: N.A. | E8: Slide No. 47 (hidden) | F8: Downwash effect | I8: Calculated | L8: Gradient | M8: =1 / ( ( C7/C5)* ( 1 - C8 ) *(C37/C22) * ( C6 ) ) -> 0.42520757 | O8: C_Law approach | P8: =C50 -> 4.7173477
B9: SM | C9: 0 | D9: N.A. | F9: Safety margin | I9: GIVEN | L9: Intercept | M9: =( C4 - C9 ) / ( ( C7/C5)* ( 1 - C8 ) *(C37/C22) * ( C6 ) ) -> 0.11970485 | O9: C_LA-h | P9: =2.027*1.2 -> 2.4324
B10: C_Lh | C10: -1 | F10: maximum for movable tails | I10: Assumed
B11: C_m_ac | C11: -0.12 | F11: from graph | I11: Assumed
B12: alpha | C12: =10*PI()/180 -> 0.17453293 | D12: rad | F12: Assumed landing glide angle of attack
B15: Geometric and aero parameters
B16: Parameter | C16: Value | D16: Unit | F16: Description
B17: x_ac_w | C17: 0.35 | D17: Fraction of MAC | F17: Wing AC contribution | I17: General knowledge | T17: FOR THE CRJ EXX
B18: b_f | C18: 2.695 | D18: [m] | F18: Fuselage width | I18: From APM | T18: nacelles have increased dimension both in length (+20%) and diameter (+20%)
B19: h_f | C19: 2.695 | D19: [m] | F19: Fuselage height | I19: From APM, assumption of circular fuselage, looks accurate (APM also specifies "diameter" so likely its round) | T19: the MTOW of the CRJ-EXX will be the same of the CRJ-1000
B20: l_fn | C20: 36.466 | D20: [m] | F20: Fuselage length | I20: From APM, but on ground, might be slightly different in flight | T20: increases the wing effective Aspect Ratio by 25% when compared to the initial CRJ-1000
B21: S_w | C21: =(E77+E76)*C24/2 -> 80.845929 | D21: [m^2] | F21: Wing planform area | I21: From APM | T21: The maximum lift coefficient of the Aircraft-less-tail is increased by 20% with respect the CRJ-1000
B22: c_MAC | C22: =E78 -> 3.3863373 | D22: [m] | F22: MAC length | I22: We have a pixel calculation, but an actual one would be nicer
B23: c_g | C23: =C21/C24 -> 3.0886697 | D23: [m] | F23: Mean geometric chord | I23: From APM
B24: b | C24: 26.175 | D24: [m] | F24: Wing span | I24: From APM
B25: taper | C25: =E76/E77 -> 0.27960928 | D25: N.A. | F25: Wing taper | I25: Calculated
B26: c/4 sweep | C26: =ATAN(TAN(RADIANS(D79))-4*0.25*(1-C25)/(C39*(1+C25))) -> 0.47990296 | D26: [rad] | F26: Wing quarter chord sweep | I26: Calculated
